Workbook

Sheet Srpint 1
A1: Project name: | C1: Xây dựng hệ thống quản lý tài chính gia đình | F1: Kết thúc đúng hạn
A2: Module name: | C2: Sprint 1 | F2: Muộn
A3: Start date: | C3: =I15 -> 46102 | F3: Trước thời hạn
A4: End date: | C4: =W15 -> 46116
B6: SPRINT 1 REPORT
B7: No | C7: Thành viên | D7: Thực tế | E7: Ước tính
B8: 1 | C8: Đức | D8: =SUMIF(E16:E104,"Đức",G16:G104)+SUMIF(E16:E104,"All team",G16:G104)/5 -> 42 | E8: =SUMIF(E16:E104,"Đức",H16:H104)+SUMIF(E16:E104,"All team",H16:H104)/5 -> 46
B9: 2 | C9: Tiên | D9: =SUMIF(E16:E104,"Tiên",G16:G104)+SUMIF(E16:E104,"All team",G16:G104)/5+SUMIF(E16:E104,"Tiên, Vũ",G16:G104)/2 -> 43 | E9: =SUMIF(E16:E104,"Tiên",H16:H104)+SUMIF(E16:E104,"All team",H16:H104)/5+SUMIF(E16:E104,"Tiên, Vũ",H16:H104)/2 -> 46
B10: 3 | C10: Vũ | D10: =SUMIF(E16:E104,"Vũ",G16:G104)+SUMIF(E16:E104,"All team",G16:G104)/5+SUMIF(E16:E104,"Tiên, Vũ",G16:G104)/2 -> 40 | E10: =SUMIF(E16:E104,"Vũ",H16:H104)+SUMIF(E16:E104,"All team",H16:H104)/5+SUMIF(E16:E104,"Tiên, Vũ",H16:H104)/2 -> 44
B11: 4 | C11: Nguyên | D11: =SUMIF(E16:E104,"Nguyên",G16:G104)+SUMIF(E16:E104,"All team",G16:G104)/5+SUMIF(E16:E104,"Nguyên, Nhã",G16:G104)/2 -> 45 | E11: =SUMIF(E16:E104,"Nguyên",H16:H104)+SUMIF(E16:E104,"All team",H16:H104)/5+SUMIF(E16:E104,"Nguyên, Nhã",H16:H104)/2 -> 46
B12: 5 | C12: Nhã | D12: =SUMIF(E16:E104,"Nhã",G16:G104)+SUMIF(E16:E104,"All team",G16:G104)/5+SUMIF(E16:E104,"Nguyên, Nhã",G16:G104)/2 -> 43 | E12: =SUMIF(E16:E104,"Nhã",H16:H104)+SUMIF(E16:E104,"All team",H16:H104)/5+SUMIF(E16:E104,"Nguyên, Nhã",H16:H104)/2 -> 46
B13: Tổng | D13: =SUM(D8:D12) -> 213 | E13: =SUM(E8:E12) -> 228
A15: Sprint | B15: Compoment | C15: Task name | E15: Responsible Member | G15: Thực tế | H15: Ước tính | I15: 46102 | J15: 46103 | K15: 46104 | L15: 46105 | M15: 46106 | N15: 46107 | O15: 46108 | P15: 46109 | Q15: 46110 | R15: 46111 | S15: 46112 | T15: 46113 | U15: 46114 | V15: 46115 | W15: 46116
A16: Sprint 1 | B16: Họp kế hoạch Sprint | E16: All team | G16: =H16-I16 -> 10 | H16: 10 | I16: 0 | J16: 0 | K16: 0 | L16: 0 | M16: 0 | N16: 0 | O16: 0 | P16: 0 | Q16: 0 | R16: 0 | S16: 0 | T16: 0 | U16: 0 | V16: 0 | W16: 0
B17: Tạo Sprint Backlog 1 | E17: Nguyên, Nhã | G17: 4 | H17: 4 | I17: 4 | J17: 0 | K17: 0 | L17: 0 | M17: 0 | N17: 0 | O17: 0 | P17: 0 | Q17: 0 | R17: 0 | S17: 0 | T17: 0 | U17: 0 | V17: 0 | W17: 0
B18: Tạo tài liệu kiểm thử cho Sprint | E18: Tiên, Vũ | G18: =H18-K18 -> 4 | H18: 4 | I18: 4 | J18: 0 | K18: 0 | L18: 0 | M18: 0 | N18: 0 | O18: 0 | P18: 0 | Q18: 0 | R18: 0 | S18: 0 | T18: 0 | U18: 0 | V18: 0 | W18: 0
B19: User interface design | C19: Đăng ký | E19: Nguyên | G19: =H19+K19 -> 2 | H19: 2 | I19: 2 | J19: 2 | K19: 0 | L19: 0 | M19: 0 | N19: 0 | O19: 0 | P19: 0 | Q19: 0 | R19: 0 | S19: 0 | T19: 0 | U19: 0 | V19: 0 | W19: 0
C20: Đăng nhập / Đăng xuất | E20: Nhã | G20: =H20+K20 -> 2 | H20: 2 | I20: 2 | J20: 2 | K20: 0 | L20: 0 | M20: 0 | N20: 0 | O20: 0 | P20: 0 | Q20: 0 | R20: 0 | S20: 0 | T20: 0 | U20: 0 | V20: 0 | W20: 0
C21: Quản lý thông tin cá nhân | E21: Tiên | G21: =H21+K21 -> 2 | H21: 2 | I21: 2 | J21: 2 | K21: 0 | L21: 0 | M21: 0 | N21: 0 | O21: 0 | P21: 0 | Q21: 0 | R21: 0 | S21: 0 | T21: 0 | U21: 0 | V21: 0 | W21: 0
C22: Quản lý phân quyền | E22: Vũ | G22: =H22+K22 -> 2 | H22: 2 | I22: 2 | J22: 2 | K22: 0 | L22: 0 | M22: 0 | N22: 0 | O22: 0 | P22: 0 | Q22: 0 | R22: 0 | S22: 0 | T22: 0 | U22: 0 | V22: 0 | W22: 0
C23: Thêm thành viên vào nhóm gia đình | E23: Đức | G23: =H23+K24 -> 1 | H23: 2 | I23: 2 | J23: 2 | K23: 0 | L23: 0 | M23: 0 | N23: 0 | O23: 0 | P23: 0 | Q23: 0 | R23: 0 | S23: 0 | T23: 0 | U23: 0 | V23: 0 | W23: 0
K24: -1
C25: Tạo phòng và gia nhập phòng | E25: Tiên | G25: =H25+K25 -> 2 | H25: 2 | I25: 2 | J25: 2 | K25: 0 | L25: 0 | M25: 0 | N25: 0 | O25: 0 | P25: 0 | Q25: 0 | R25: 0 | S25: 0 | T25: 0 | U25: 0 | V25: 0 | W25: 0
C26: Xóa thành viên khỏi nhóm gia đình | E26: Nhã | G26: =H26+K26 -> 2 | H26: 2 | I26: 2 | J26: 2 | K26: 0 | L26: 0 | M26: 0 | N26: 0 | O26: 0 | P26: 0 | Q26: 0 | R26: 0 | S26: 0 | T26: 0 | U26: 0 | V26: 0 | W26: 0
C27: Thêm khoản thu | E27: Tiên | G27: =H27+K27 -> 2 | H27: 2 | I27: 2 | J27: 2 | K27: 0 | L27: 0 | M27: 0 | N27: 0 | O27: 0 | P27: 0 | Q27: 0 | R27: 0 | S27: 0 | T27: 0 | U27: 0 | V27: 0 | W27: 0
C28: Xem danh sách khoản thu | E28: Vũ | G28: =H28+K28 -> 2 | H28: 2 | I28: 2 | J28: 2 | K28: 0 | L28: 0 | M28: 0 | N28: 0 | O28: 0 | P28: 0 | Q28: 0 | R28: 0 | S28: 0 | T28: 0 | U28: 0 | V28: 0 | W28: 0
C29: Xem chi tiết khoản thu | E29: Vũ | G29: =H29+K30 -> 1 | H29: 2 | I29: 2 | J29: 2 | K29: 0 | L29: 0 | M29: 0 | N29: 0 | O29: 0 | P29: 0 | Q29: 0 | R29: 0 | S29: 0 | T29: 0 | U29: 0 | V29: 0 | W29: 0
K30: -1
C31: Review all user interfaces of sprint 1 | E31: All team | G31: =H31+K32 -> 5 | H31: 10 | I31: 10 | J31: 10 | K31: 0 | L31: 0 | M31: 0 | N31: 0 | O31: 0 | P31: 0 | Q31: 0 | R31: 0 | S31: 0 | T31: 0 | U31: 0 | V31: 0 | W31: 0
K32: -5
B33: Design test case | C33: Đăng ký | E33: Nguyên | G33: =H33+L33 -> 2 | H33: 2 | I33: 2 | J33: 2 | K33: 2 | L33: 0 | M33: 0 | N33: 0 | O33: 0 | P33: 0 | Q33: 0 | R33: 0 | S33: 0 | T33: 0 | U33: 0 | V33: 0 | W33: 0
C34: Đăng nhập / Đăng xuất | E34: Nhã | G34: =H34+L34 -> 2 | H34: 2 | I34: 2 | J34: 2 | K34: 2 | L34: 0 | M34: 0 | N34: 0 | O34: 0 | P34: 0 | Q34: 0 | R34: 0 | S34: 0 | T34: 0 | U34: 0 | V34: 0 | W34: 0
C35: Quản lý thông tin cá nhân | E35: Tiên | G35: =H35+L35 -> 2 | H35: 2 | I35: 2 | J35: 2 | K35: 2 | L35: 0 | M35: 0 | N35: 0 | O35: 0 | P35: 0 | Q35: 0 | R35: 0 | S35: 0 | T35: 0 | U35: 0 | V35: 0 | W35: 0
C36: Quản lý phân quyền | E36: Vũ | G36: =H36+L36 -> 2 | H36: 2 | I36: 2 | J36: 2 | K36: 2 | L36: 0 | M36: 0 | N36: 0 | O36: 0 | P36: 0 | Q36: 0 | R36: 0 | S36: 0 | T36: 0 | U36: 0 | V36: 0 | W36: 0
C37: Thêm thành viên vào nhóm gia đình | E37: Đức | G37: =H37+L37 -> 2 | H37: 2 | I37: 2 | J37: 2 | K37: 2 | L37: 0 | M37: 0 | N37: 0 | O37: 0 | P37: 0 | Q37: 0 | R37: 0 | S37: 0 | T37: 0 | U37: 0 | V37: 0 | W37: 0
C38: Tạo phòng và gia nhập phòng | E38: Tiên | G38: =H38+L38 -> 2 | H38: 2 | I38: 2 | J38: 2 | K38: 2 | L38: 0 | M38: 0 | N38: 0 | O38: 0 | P38: 0 | Q38: 0 | R38: 0 | S38: 0 | T38: 0 | U38: 0 | V38: 0 | W38: 0
C39: Xóa thành viên khỏi nhóm gia đình | E39: Nhã | G39: =H39+L39 -> 2 | H39: 2 | I39: 2 | J39: 2 | K39: 2 | L39: 0 | M39: 0 | N39: 0 | O39: 0 | P39: 0 | Q39: 0 | R39: 0 | S39: 0 | T39: 0 | U39: 0 | V39: 0 | W39: 0
C40: Thêm khoản thu | E40: Tiên | G40: =H40+L40 -> 2 | H40: 2 | I40: 2 | J40: 2 | K40: 2 | L40: 0 | M40: 0 | N40: 0 | O40: 0 | P40: 0 | Q40: 0 | R40: 0 | S40: 0 | T40: 0 | U40: 0 | V40: 0 | W40: 0
C41: Xem danh sách khoản thu | E41: Vũ | G41: =H41+L41 -> 2 | H41: 2 | I41: 2 | J41: 2 | K41: 2 | L41: 0 | M41: 0 | N41: 0 | O41: 0 | P41: 0 | Q41: 0 | R41: 0 | S41: 0 | T41: 0 | U41: 0 | V41: 0 | W41: 0
C42: Xem chi tiết khoản thu | E42: Đức | G42: =H42+L42 -> 2 | H42: 2 | I42: 2 | J42: 2 | K42: 2 | L42: 0 | M42: 0 | N42: 0 | O42: 0 | P42: 0 | Q42: 0 | R42: 0 | S42: 0 | T42: 0 | U42: 0 | V42: 0 | W42: 0
...

Sheet Sprint 2
A1: Project name: | C1: Xây dựng hệ thống quản lý tài chính gia đình | F1: Kết thúc đúng hạn
A2: Module name: | C2: Sprint 2 | F2: Muộn
A3: Start date: | C3: =I15 -> 46117 | F3: Trước thời hạn
A4: End date: | C4: =W15 -> 46131
B6: SPRINT 2 REPORT
B7: No | C7: Thành viên | D7: Thực tế | E7: Ước tính
B8: 1 | C8: Đức | D8: =SUMIF(E16:E107,"Đức",G16:G107)+SUMIF(E16:E107,"All team",G16:G107)/5 -> 46 | E8: =SUMIF(E16:E107,"Đức",H16:H107)+SUMIF(E16:E107,"All team",H16:H107)/5 -> 50
B9: 2 | C9: Tiên | D9: =SUMIF(E16:E107,"Tiên",G16:G107)+SUMIF(E16:E107,"All team",G16:G107)/5+SUMIF(E16:E107,"Tiên, Vũ",G16:G107)/2 -> 39 | E9: =SUMIF(E16:E107,"Tiên",H16:H107)+SUMIF(E16:E107,"All team",H16:H107)/5+SUMIF(E16:E107,"Tiên, Vũ",H16:H107)/2 -> 42
B10: 3 | C10: Vũ | D10: =SUMIF(E16:E107,"Vũ",G16:G107)+SUMIF(E16:E107,"All team",G16:G107)/5+SUMIF(E16:E107,"Tiên, Vũ",G16:G107)/2 -> 39 | E10: =SUMIF(E16:E107,"Vũ",H16:H107)+SUMIF(E16:E107,"All team",H16:H107)/5+SUMIF(E16:E107,"Tiên, Vũ",H16:H107)/2 -> 42
B11: 4 | C11: Nguyên | D11: =SUMIF(E16:E107,"Nguyên",G16:G107)+SUMIF(E16:E107,"All team",G16:G107)/5+SUMIF(E16:E107,"Nguyên, Nhã",G16:G107)/2 -> 46 | E11: =SUMIF(E16:E107,"Nguyên",H16:H107)+SUMIF(E16:E107,"All team",H16:H107)/5+SUMIF(E16:E107,"Nguyên, Nhã",H16:H107)/2 -> 48
B12: 5 | C12: Nhã | D12: =SUMIF(E16:E107,"Nhã",G16:G107)+SUMIF(E16:E107,"All team",G16:G107)/5+SUMIF(E16:E107,"Nguyên, Nhã",G16:G107)/2 -> 48 | E12: =SUMIF(E16:E107,"Nhã",H16:H107)+SUMIF(E16:E107,"All team",H16:H107)/5+SUMIF(E16:E107,"Nguyên, Nhã",H16:H107)/2 -> 46
B13: Tổng | D13: =SUM(D8:D12) -> 218 | E13: =SUM(E8:E12) -> 228
A15: Sprint | B15: Compoment | C15: Task name | E15: Responsible Member | G15: Thực tế | H15: Ước tính | I15: 46117 | J15: 46118 | K15: 46119 | L15: 46120 | M15: 46121 | N15: 46122 | O15: 46123 | P15: 46124 | Q15: 46125 | R15: 46126 | S15: 46127 | T15: 46128 | U15: 46129 | V15: 46130 | W15: 46131
A16: Sprint 2 | B16: Họp kế hoạch Sprint | E16: All team | G16: =H16-I16 -> 10 | H16: 10 | I16: 0 | J16: 0 | K16: 0 | L16: 0 | M16: 0 | N16: 0 | O16: 0 | P16: 0 | Q16: 0 | R16: 0 | S16: 0 | T16: 0 | U16: 0 | V16: 0 | W16: 0
B17: Tạo Sprint Backlog 2 | E17: Nguyên, Nhã | G17: 4 | H17: 4 | I17: 4 | J17: 0 | K17: 0 | L17: 0 | M17: 0 | N17: 0 | O17: 0 | P17: 0 | Q17: 0 | R17: 0 | S17: 0 | T17: 0 | U17: 0 | V17: 0 | W17: 0
B18: Tạo tài liệu kiểm thử cho Sprint | E18: Tiên, Vũ | G18: =H18-K18 -> 4 | H18: 4 | I18: 4 | J18: 0 | K18: 0 | L18: 0 | M18: 0 | N18: 0 | O18: 0 | P18: 0 | Q18: 0 | R18: 0 | S18: 0 | T18: 0 | U18: 0 | V18: 0 | W18: 0
B19: User interface design | C19: Sửa khoản thu | E19: Tiên | G19: =H19+K20 -> 1 | H19: 2 | I19: 2 | J19: 2 | K19: 0 | L19: 0 | M19: 0 | N19: 0 | O19: 0 | P19: 0 | Q19: 0 | R19: 0 | S19: 0 | T19: 0 | U19: 0 | V19: 0 | W19: 0
K20: -1
C21: Xóa khoản thu | E21: Vũ | G21: =H21+K22 -> 1 | H21: 2 | I21: 2 | J21: 2 | K21: 0 | L21: 0 | M21: 0 | N21: 0 | O21: 0 | P21: 0 | Q21: 0 | R21: 0 | S21: 0 | T21: 0 | U21: 0 | V21: 0 | W21: 0
K22: -1
C23: Phân loại thu chi | E23: Tiên | G23: 2 | H23: 2 | I23: 2 | J23: 2 | K23: 0 | L23: 0 | M23: 0 | N23: 0 | O23: 0 | P23: 0 | Q23: 0 | R23: 0 | S23: 0 | T23: 0 | U23: 0 | V23: 0 | W23: 0
C24: Nhập thu chi bằng giọng nói (AI) | E24: Nguyên | G24: 2 | H24: 2 | I24: 2 | J24: 2 | K24: 0 | L24: 0 | M24: 0 | N24: 0 | O24: 0 | P24: 0 | Q24: 0 | R24: 0 | S24: 0 | T24: 0 | U24: 0 | V24: 0 | W24: 0
C25: Thêm khoản chi | E25: Nhã | G25: 2 | H25: 2 | I25: 2 | J25: 2 | K25: 0 | L25: 0 | M25: 0 | N25: 0 | O25: 0 | P25: 0 | Q25: 0 | R25: 0 | S25: 0 | T25: 0 | U25: 0 | V25: 0 | W25: 0
C26: Xem danh sách khoản chi | E26: Tiên | G26: 2 | H26: 2 | I26: 2 | J26: 2 | K26: 0 | L26: 0 | M26: 0 | N26: 0 | O26: 0 | P26: 0 | Q26: 0 | R26: 0 | S26: 0 | T26: 0 | U26: 0 | V26: 0 | W26: 0
C27: Xem chi tiết khoản chi | E27: Vũ | G27: 2 | H27: 2 | I27: 2 | J27: 2 | K27: 0 | L27: 0 | M27: 0 | N27: 0 | O27: 0 | P27: 0 | Q27: 0 | R27: 0 | S27: 0 | T27: 0 | U27: 0 | V27: 0 | W27: 0
C28: Sửa khoản chi | E28: Vũ | G28: 2 | H28: 2 | I28: 2 | J28: 2 | K28: 0 | L28: 0 | M28: 0 | N28: 0 | O28: 0 | P28: 0 | Q28: 0 | R28: 0 | S28: 0 | T28: 0 | U28: 0 | V28: 0 | W28: 0
C29: Xóa khoản chi | E29: Vũ | G29: 2 | H29: 2 | I29: 2 | J29: 2 | K29: 0 | L29: 0 | M29: 0 | N29: 0 | O29: 0 | P29: 0 | Q29: 0 | R29: 0 | S29: 0 | T29: 0 | U29: 0 | V29: 0 | W29: 0
C30: Gắn thẻ (tag) cho khoản chi | E30: Nhã | G30: 2 | H30: 2 | I30: 2 | J30: 2 | K30: 0 | L30: 0 | M30: 0 | N30: 0 | O30: 0 | P30: 0 | Q30: 0 | R30: 0 | S30: 0 | T30: 0 | U30: 0 | V30: 0 | W30: 0
C31: Review all user interfaces of sprint 2 | E31: All team | G31: 10 | H31: 10 | I31: 10 | J31: 10 | K31: 0 | L31: 0 | M31: 0 | N31: 0 | O31: 0 | P31: 0 | Q31: 0 | R31: 0 | S31: 0 | T31: 0 | U31: 0 | V31: 0 | W31: 0
B32: Design test case | C32: Sửa khoản thu | E32: Tiên | G32: =H32+L33 -> 1 | H32: 2 | I32: 2 | J32: 2 | K32: 2 | L32: 0 | M32: 0 | N32: 0 | O32: 0 | P32: 0 | Q32: 0 | R32: 0 | S32: 0 | T32: 0 | U32: 0 | V32: 0 | W32: 0
L33: -1
C34: Xóa khoản thu | E34: Vũ | G34: =H34+L35 -> 1 | H34: 2 | I34: 2 | J34: 2 | K34: 2 | L34: 0 | M34: 0 | N34: 0 | O34: 0 | P34: 0 | Q34: 0 | R34: 0 | S34: 0 | T34: 0 | U34: 0 | V34: 0 | W34: 0
L35: -1
C36: Phân loại thu chi | E36: Tiên | G36: 2 | H36: 2 | I36: 2 | J36: 2 | K36: 2 | L36: 0 | M36: 0 | N36: 0 | O36: 0 | P36: 0 | Q36: 0 | R36: 0 | S36: 0 | T36: 0 | U36: 0 | V36: 0 | W36: 0
C37: Nhập thu chi bằng giọng nói (AI) | E37: Nguyên | G37: 2 | H37: 2 | I37: 2 | J37: 2 | K37: 2 | L37: 0 | M37: 0 | N37: 0 | O37: 0 | P37: 0 | Q37: 0 | R37: 0 | S37: 0 | T37: 0 | U37: 0 | V37: 0 | W37: 0
C38: Thêm khoản chi | E38: Nhã | G38: 2 | H38: 2 | I38: 2 | J38: 2 | K38: 2 | L38: 0 | M38: 0 | N38: 0 | O38: 0 | P38: 0 | Q38: 0 | R38: 0 | S38: 0 | T38: 0 | U38: 0 | V38: 0 | W38: 0
C39: Xem danh sách khoản chi | E39: Tiên | G39: 2 | H39: 2 | I39: 2 | J39: 2 | K39: 2 | L39: 0 | M39: 0 | N39: 0 | O39: 0 | P39: 0 | Q39: 0 | R39: 0 | S39: 0 | T39: 0 | U39: 0 | V39: 0 | W39: 0
C40: Xem chi tiết khoản chi | E40: Vũ | G40: 2 | H40: 2 | I40: 2 | J40: 2 | K40: 2 | L40: 0 | M40: 0 | N40: 0 | O40: 0 | P40: 0 | Q40: 0 | R40: 0 | S40: 0 | T40: 0 | U40: 0 | V40: 0 | W40: 0
C41: Sửa khoản chi | E41: Đức | G41: 2 | H41: 2 | I41: 2 | J41: 2 | K41: 2 | L41: 0 | M41: 0 | N41: 0 | O41: 0 | P41: 0 | Q41: 0 | R41: 0 | S41: 0 | T41: 0 | U41: 0 | V41: 0 | W41: 0
C42: Xóa khoản chi | E42: Nguyên | G42: 2 | H42: 2 | I42: 2 | J42: 2 | K42: 2 | L42: 0 | M42: 0 | N42: 0 | O42: 0 | P42: 0 | Q42: 0 | R42: 0 | S42: 0 | T42: 0 | U42: 0 | V42: 0 | W42: 0
...

Sheet Sprint 3
A1: Project name: | C1: Xây dựng hệ thống quản lý tài chính gia đình | F1: Kết thúc đúng hạn
A2: Module name: | C2: Sprint 3 | F2: Muộn
A3: Start date: | C3: =I15 -> 46132 | F3: Trước thời hạn
A4: End date: | C4: =W15 -> 46146
B6: SPRINT 3 REPORT
B7: No | C7: Thành viên | D7: Thực tế | E7: Ước tính
B8: 1 | C8: Đức | D8: =SUMIF(E16:E98,"Đức",G16:G98)+SUMIF(E16:E98,"All team",G16:G98)/5 -> 55 | E8: =SUMIF(E16:E98,"Đức",H16:H98)+SUMIF(E16:E98,"All team",H16:H98)/5 -> 60
B9: 2 | C9: Tiên | D9: =SUMIF(E16:E98,"Tiên",G16:G98)+SUMIF(E16:E98,"All team",G16:G98)/5+SUMIF(E16:E98,"Tiên, Vũ",G16:G98)/2 -> 33 | E9: =SUMIF(E16:E98,"Tiên",H16:H98)+SUMIF(E16:E98,"All team",H16:H98)/5+SUMIF(E16:E98,"Tiên, Vũ",H16:H98)/2 -> 40
B10: 3 | C10: Vũ | D10: =SUMIF(E16:E98,"Vũ",G16:G98)+SUMIF(E16:E98,"All team",G16:G98)/5+SUMIF(E16:E98,"Tiên, Vũ",G16:G98)/2 -> 39 | E10: =SUMIF(E16:E98,"Vũ",H16:H98)+SUMIF(E16:E98,"All team",H16:H98)/5+SUMIF(E16:E98,"Tiên, Vũ",H16:H98)/2 -> 42
B11: 4 | C11: Nguyên | D11: =SUMIF(E16:E98,"Nguyên",G16:G98)+SUMIF(E16:E98,"All team",G16:G98)/5+SUMIF(E16:E98,"Nguyên, Nhã",G16:G98)/2 -> 62 | E11: =SUMIF(E16:E98,"Nguyên",H16:H98)+SUMIF(E16:E98,"All team",H16:H98)/5+SUMIF(E16:E98,"Nguyên, Nhã",H16:H98)/2 -> 60
B12: 5 | C12: Nhã | D12: =SUMIF(E16:E98,"Nhã",G16:G98)+SUMIF(E16:E98,"All team",G16:G98)/5+SUMIF(E16:E98,"Nguyên, Nhã",G16:G98)/2 -> 34 | E12: =SUMIF(E16:E98,"Nhã",H16:H98)+SUMIF(E16:E98,"All team",H16:H98)/5+SUMIF(E16:E98,"Nguyên, Nhã",H16:H98)/2 -> 36
B13: Tổng | D13: =SUM(D8:D12) -> 223 | E13: =SUM(E8:E12) -> 238
A15: Sprint | B15: Compoment | C15: Task name | E15: Responsible Member | G15: Thực tế | H15: Ước tính | I15: 46132 | J15: 46133 | K15: 46134 | L15: 46135 | M15: 46136 | N15: 46137 | O15: 46138 | P15: 46139 | Q15: 46140 | R15: 46141 | S15: 46142 | T15: 46143 | U15: 46144 | V15: 46145 | W15: 46146
A16: Sprint 1 | B16: Họp kế hoạch Sprint | E16: All team | G16: =H16-I16 -> 10 | H16: 10 | I16: 0 | J16: 0 | K16: 0 | L16: 0 | M16: 0 | N16: 0 | O16: 0 | P16: 0 | Q16: 0 | R16: 0 | S16: 0 | T16: 0 | U16: 0 | V16: 0 | W16: 0
B17: Tạo Sprint Backlog 3 | E17: Nguyên, Nhã | G17: 4 | H17: 4 | I17: 4 | J17: 0 | K17: 0 | L17: 0 | M17: 0 | N17: 0 | O17: 0 | P17: 0 | Q17: 0 | R17: 0 | S17: 0 | T17: 0 | U17: 0 | V17: 0 | W17: 0
B18: Tạo tài liệu kiểm thử cho Sprint | E18: Tiên, Vũ | G18: =H18-K18 -> 4 | H18: 4 | I18: 4 | J18: 0 | K18: 0 | L18: 0 | M18: 0 | N18: 0 | O18: 0 | P18: 0 | Q18: 0 | R18: 0 | S18: 0 | T18: 0 | U18: 0 | V18: 0 | W18: 0
B19: User interface design | C19: Báo cáo & Thống kê | E19: Tiên | G19: 2 | H19: 2 | I19: 2 | J19: 2 | K19: 0 | L19: 0 | M19: 0 | N19: 0 | O19: 0 | P19: 0 | Q19: 0 | R19: 0 | S19: 0 | T19: 0 | U19: 0 | V19: 0 | W19: 0
C20: Phân tích tài chính (AI) | E20: Vũ | G20: 2 | H20: 2 | I20: 2 | J20: 2 | K20: 0 | L20: 0 | M20: 0 | N20: 0 | O20: 0 | P20: 0 | Q20: 0 | R20: 0 | S20: 0 | T20: 0 | U20: 0 | V20: 0 | W20: 0
C21: Cảnh báo tài chính | E21: Đức | G21: 2 | H21: 2 | I21: 2 | J21: 2 | K21: 0 | L21: 0 | M21: 0 | N21: 0 | O21: 0 | P21: 0 | Q21: 0 | R21: 0 | S21: 0 | T21: 0 | U21: 0 | V21: 0 | W21: 0
C22: Quản lý ngân sách | E22: Nguyên | G22: =H22+K23 -> 3 | H22: 2 | I22: 2 | J22: 2 | K22: 0 | L22: 0 | M22: 0 | N22: 0 | O22: 0 | P22: 0 | Q22: 0 | R22: 0 | S22: 0 | T22: 0 | U22: 0 | V22: 0 | W22: 0
K23: 1
C24: Quản lý kế hoạch tài chính | E24: Nhã | G24: 2 | H24: 2 | I24: 2 | J24: 2 | K24: 0 | L24: 0 | M24: 0 | N24: 0 | O24: 0 | P24: 0 | Q24: 0 | R24: 0 | S24: 0 | T24: 0 | U24: 0 | V24: 0 | W24: 0
C25: Thông báo & nhắc nhở | E25: Tiên | G25: 2 | H25: 2 | I25: 2 | J25: 2 | K25: 0 | L25: 0 | M25: 0 | N25: 0 | O25: 0 | P25: 0 | Q25: 0 | R25: 0 | S25: 0 | T25: 0 | U25: 0 | V25: 0 | W25: 0
C26: Tìm kiếm & lọc dữ liệu | E26: Vũ | G26: 2 | H26: 2 | I26: 2 | J26: 2 | K26: 0 | L26: 0 | M26: 0 | N26: 0 | O26: 0 | P26: 0 | Q26: 0 | R26: 0 | S26: 0 | T26: 0 | U26: 0 | V26: 0 | W26: 0
C27: Quản lý tài khoản người dùng (Admin) | E27: Tiên | G27: 2 | H27: 2 | I27: 2 | J27: 2 | K27: 0 | L27: 0 | M27: 0 | N27: 0 | O27: 0 | P27: 0 | Q27: 0 | R27: 0 | S27: 0 | T27: 0 | U27: 0 | V27: 0 | W27: 0
C28: Quản lý danh mục (Admin) | E28: Nhã | G28: 2 | H28: 2 | I28: 2 | J28: 2 | K28: 0 | L28: 0 | M28: 0 | N28: 0 | O28: 0 | P28: 0 | Q28: 0 | R28: 0 | S28: 0 | T28: 0 | U28: 0 | V28: 0 | W28: 0
C29: Review all user interfaces of sprint 3 | E29: All team | G29: =H29+K30 -> 5 | H29: 10 | I29: 10 | J29: 10 | K29: 0 | L29: 0 | M29: 0 | N29: 0 | O29: 0 | P29: 0 | Q29: 0 | R29: 0 | S29: 0 | T29: 0 | U29: 0 | V29: 0 | W29: 0
K30: -5
B31: Design test case | C31: Báo cáo & Thống kê | E31: Tiên | G31: =H31+L32 -> 1 | H31: 2 | I31: 2 | J31: 2 | K31: 2 | L31: 0 | M31: 0 | N31: 0 | O31: 0 | P31: 0 | Q31: 0 | R31: 0 | S31: 0 | T31: 0 | U31: 0 | V31: 0 | W31: 0
L32: -1
C33: Phân tích tài chính (AI) | E33: Vũ | G33: 2 | H33: 2 | I33: 2 | J33: 2 | K33: 2 | L33: 0 | M33: 0 | N33: 0 | O33: 0 | P33: 0 | Q33: 0 | R33: 0 | S33: 0 | T33: 0 | U33: 0 | V33: 0 | W33: 0
C34: Cảnh báo tài chính | E34: Đức | G34: 2 | H34: 2 | I34: 2 | J34: 2 | K34: 2 | L34: 0 | M34: 0 | N34: 0 | O34: 0 | P34: 0 | Q34: 0 | R34: 0 | S34: 0 | T34: 0 | U34: 0 | V34: 0 | W34: 0
C35: Quản lý ngân sách | E35: Nguyên | G35: 2 | H35: 2 | I35: 2 | J35: 2 | K35: 2 | L35: 0 | M35: 0 | N35: 0 | O35: 0 | P35: 0 | Q35: 0 | R35: 0 | S35: 0 | T35: 0 | U35: 0 | V35: 0 | W35: 0
C36: Quản lý kế hoạch tài chính | E36: Nhã | G36: 2 | H36: 2 | I36: 2 | J36: 2 | K36: 2 | L36: 0 | M36: 0 | N36: 0 | O36: 0 | P36: 0 | Q36: 0 | R36: 0 | S36: 0 | T36: 0 | U36: 0 | V36: 0 | W36: 0
C37: Thông báo & nhắc nhở | E37: Tiên | G37: 2 | H37: 2 | I37: 2 | J37: 2 | K37: 2 | L37: 0 | M37: 0 | N37: 0 | O37: 0 | P37: 0 | Q37: 0 | R37: 0 | S37: 0 | T37: 0 | U37: 0 | V37: 0 | W37: 0
C38: Tìm kiếm & lọc dữ liệu | E38: Vũ | G38: 2 | H38: 2 | I38: 2 | J38: 2 | K38: 2 | L38: 0 | M38: 0 | N38: 0 | O38: 0 | P38: 0 | Q38: 0 | R38: 0 | S38: 0 | T38: 0 | U38: 0 | V38: 0 | W38: 0
C39: Quản lý tài khoản người dùng (Admin) | E39: Đức | G39: 2 | H39: 2 | I39: 2 | J39: 2 | K39: 2 | L39: 0 | M39: 0 | N39: 0 | O39: 0 | P39: 0 | Q39: 0 | R39: 0 | S39: 0 | T39: 0 | U39: 0 | V39: 0 | W39: 0
C40: Quản lý danh mục (Admin) | E40: Nhã | G40: 2 | H40: 2 | I40: 2 | J40: 2 | K40: 2 | L40: 0 | M40: 0 | N40: 0 | O40: 0 | P40: 0 | Q40: 0 | R40: 0 | S40: 0 | T40: 0 | U40: 0 | V40: 0 | W40: 0
C41: Review all test case of sprint 3 | E41: All team | G41: =H41+L42 -> 5 | H41: 10 | I41: 10 | J41: 10 | K41: 10 | L41: 0 | M41: 0 | N41: 0 | O41: 0 | P41: 0 | Q41: 0 | R41: 0 | S41: 0 | T41: 0 | U41: 0 | V41: 0 | W41: 0
L42: -5
...

Sheet Total
A1: SPRINT BACKLOG REPORT
B2: Đức | D2: Tiên | F2: Vũ | H2: Nguyên | J2: Nhã
B3: Thực tế | C3: Ước tính | D3: Thực tế | E3: Ước tính | F3: Thực tế | G3: Ước tính | H3: Thực tế | I3: Ước tính | J3: Thực tế | K3: Ước tính
A4: Sprint 1 | B4: ='Srpint 1'!D8 -> 42 | C4: ='Srpint 1'!E8 -> 46 | D4: ='Srpint 1'!D9 -> 43 | E4: ='Srpint 1'!E9 -> 46 | F4: ='Srpint 1'!D10 -> 40 | G4: ='Srpint 1'!E10 -> 44 | H4: ='Srpint 1'!D11 -> 45 | I4: ='Srpint 1'!E11 -> 46 | J4: ='Srpint 1'!D12 -> 43 | K4: ='Srpint 1'!E12 -> 46
A5: Sprint 2 | B5: ='Sprint 2'!D8 -> 46 | C5: ='Sprint 2'!E8 -> 50 | D5: ='Sprint 2'!D9 -> 39 | E5: ='Sprint 2'!E9 -> 42 | F5: ='Sprint 2'!D10 -> 39 | G5: ='Sprint 2'!E10 -> 42 | H5: ='Sprint 2'!D11 -> 46 | I5: ='Sprint 2'!E11 -> 48 | J5: ='Sprint 2'!D12 -> 48 | K5: ='Sprint 2'!E12 -> 46
A6: Sprint 3 | B6: ='Sprint 3'!D8 -> 55 | C6: ='Sprint 3'!E8 -> 60 | D6: ='Sprint 3'!D9 -> 33 | E6: ='Sprint 3'!E9 -> 40 | F6: ='Sprint 3'!D10 -> 39 | G6: ='Sprint 3'!E10 -> 42 | H6: ='Sprint 3'!D11 -> 62 | I6: ='Sprint 3'!E11 -> 60 | J6: ='Sprint 3'!D12 -> 34 | K6: ='Sprint 3'!E12 -> 36
A7: Tổng | B7: =SUM(B4:B6) -> 143 | C7: =SUM(C4:C6) -> 156 | D7: =SUM(D4:D6) -> 115 | E7: =SUM(E4:E6) -> 128 | F7: =SUM(F4:F6) -> 118 | G7: =SUM(G4:G6) -> 128 | H7: =SUM(H4:H6) -> 153 | I7: =SUM(I4:I6) -> 154 | ... K7: =SUM(K4:K6) -> 128
E10: FINAL TOTAL
E11: Thực tế | F11: =SUMIF(B3:K3,"Thực tế",B7:K7) -> 654
E12: Ước tính | F12: =SUMIF(B3:K3,"Ước tính",B7:K7) -> 694
